Workbook

Sheet Hướng dẫn chung
A1: HƯỚNG DẪN CHUNG LẬP DỰ TOÁN THỰC HIỆN NHIỆM VỤ KH&CN
A2: Stt | B2: Nội dung | C2: Hướng dẫn
A3: 1 | B3: Thù lao tham gia nhiệm vụ | C3: Bước 1: Điền định mức thù lao tháng của chủ nhiệm đề tài (DMCN) (tối đa 40 triệu đồng/tháng)
C4: Bước 2: Điền nội dung, công việc tương ứng (có chi thù lao tham gia cho các thành viên) theo kế hoạch dự kiến trong mục "Kế hoạch triển khai" của Thuyết minh đề tài. Lưu ý: - Nội dung nghiên cứu đã được tính vào thù lao thực hiện đề tài, không được trùng lắp với nội dung dịch vụ thuê ngoài - Thời gian đi điều tra, khảo sát, thu thập dữ liệu không tính vào thời gian quy đổi để chi thù lao tham gia thực hiện nhiệm vụ, chỉ tính công tác phí và chi phí điều tra, xử lý số liệu.
C5: Bước 3: Điền tên thành viên theo kế hoạch dự kiến trong mục "Kế hoạch triển khai" của Thuyết minh đề tài., số tháng làm việc quy đổi của từng thành viên tương ứng
C6: Lưu ý:
C7: - Ghi rõ chức danh khoa học, học vị, họ tên từng thành viên tham gia nghiên cứu đề tài
C8: - Mỗi nội dung được chủ trì thực hiện bởi tối đa một thành viên chính (VD: TS. Nguyễn Văn A là thành viên chính của nội dung 1 thì thành viên chính của các công việc 1, 2, 3,… trong nội dung 1 đều phải do TS. Nguyễn Văn A chủ trì)
C9: - Chủ nhiệm đề tài có thể thêm hoặc bớt dòng tuỳ theo số lượng thành viên, kỹ thuật viên tham gia nội dung nghiên cứu.
C10: - Nếu số ngày quy đổi không đủ tháng thì số tháng thực hiện nhiệm vụ được quy đổi = số ngày dự kiến thực hiện nội dung, công việc theo kế hoạch trong thuyết minh/22
C11: - Sau khi điền các bước 1,2,3, tiền công lao động khoa học theo từng nội dung công việc sẽ được tính theo công thức và tự động kết nối sang sheet Tổng kinh phí.
A12: 2 | B12: Kinh phí quản lý | C12: Bằng đúng 5% tổng kinh phí thực hiện đề tài (Đã lập sẵn công thức tính)

Sheet Tổng kinh phí
A1: Phụ lục
A2: DỰ TOÁN KINH PHÍ THỰC HIỆN ĐỀ TÀI
I3: Đơn vị tính: triệu đồng
A4: TT | B4: Nội dung các khoản chi | C4: Tổng kinh phí | D4: Nguồn vốn
D5: Kinh phí Bệnh viện | J5: Tự có | K5: Khác
D6: Tổng số | E6: Trong đó, khoán chi theo quy định* | F6: Năm thứ nhất | G6: Trong đó, khoán chi theo quy định* | H6: Năm thứ hai | I6: Trong đó, khoán chi theo quy định *
A7: 1 | B7: 2 | C7: 3 | D7: 4=(6+8+10) | E7: 5=(7+9+11) | F7: 6 | G7: 7 | H7: 8 | I7: 9 | J7: 10 | K7: 11
A8: 1 | B8: Chi thù lao thực hiện đề tài | C8: ='1a.Thulaothamgianhiemvu-12Thang'!$H$43 -> 28.394182 | D8: ='1a.Thulaothamgianhiemvu-12Thang'!$H$43 -> 28.394182 | E8: ='1a.Thulaothamgianhiemvu-12Thang'!$H$43 -> 28.394182 | F8: ='1a.Thulaothamgianhiemvu-12Thang'!$I$43 -> 28.394182 | G8: ='1a.Thulaothamgianhiemvu-12Thang'!$I$43 -> 28.394182
A9: 2 | B9: Thuê chuyên gia - Trong nước - Nước ngoài
A10: 3 | B10: Nguyên vật liệu, năng lượng
A11: 4 | B11: Thiết bị, máy móc
A12: 5 | B12: Xây dựng, sửa chữa nhỏ
A13: 6 | B13: Chi khác | C13: ='5. Chi khác'!$E$15 -> 1.4944306 | D13: ='5. Chi khác'!E15 -> 1.4944306 | E13: ='5. Chi khác'!F15 -> 1.4944306 | F13: ='5. Chi khác'!G15 -> 1.4944306 | G13: ='5. Chi khác'!H15 -> 1.4944306
B14: Tổng cộng | C14: =SUM(C8:C13) -> 29.888612 | D14: =SUM(D8:D13) -> 29.888612 | E14: =SUM(E8:E13) -> 29.888612 | F14: =SUM(F8:F13) -> 29.888612 | G14: =SUM(G8:G13) -> 29.888612

Sheet 1a Thù lao các chức danh
A2: Khoản 1. Thù lao tham gia thực hiện đề tài
A3: TỔNG HỢP DỰ TOÁN CHI THÙ LAO THỰC HIỆN ĐỀ TÀI
A5: Số TT | B5: Chức danh | C5: Tổng số người | D5: Tổng số tháng công quy đổi | E5: Tổng kinh phí (triệu đồng)
E6: Kinh phí Bệnh viện | F6: Ngoài kinh phí Bệnh viện
A7: 1 | B7: Chủ nhiệm đề tài | C7: 1 | D7: ='1a.Thulaothamgianhiemvu-12Thang'!H51 -> 2.4 | E7: ='1a.Thulaothamgianhiemvu-12Thang'!I51 -> 4.32
A8: 2 | B8: Thư ký khoa học | C8: 1 | D8: ='1a.Thulaothamgianhiemvu-12Thang'!H52 -> 2.4 | E8: ='1a.Thulaothamgianhiemvu-12Thang'!I52 -> 1.296
A9: 3 | B9: Thành viên chính | C9: 3 | D9: ='1a.Thulaothamgianhiemvu-12Thang'!H53 -> 4.7272727 | E9: ='1a.Thulaothamgianhiemvu-12Thang'!I53 -> 6.8072727
A10: 4 | B10: Thành viên | C10: 3 | D10: ='1a.Thulaothamgianhiemvu-12Thang'!H54 -> 22.181818 | E10: ='1a.Thulaothamgianhiemvu-12Thang'!I54 -> 15.970909
A11: 5 | B11: Kỹ thuật viên, nhân viên hỗ trợ | C11: 0 | D11: ='1a.Thulaothamgianhiemvu-12Thang'!H55 -> 0 | E11: ='1a.Thulaothamgianhiemvu-12Thang'!I55 -> 0
A12: Cộng: | D12: ='1a.Thulaothamgianhiemvu-12Thang'!H56 -> 31.709091 | E12: ='1a.Thulaothamgianhiemvu-12Thang'!I56 -> 28.394182

Sheet 1a.Thulaothamgianhiemvu-12Thang
A1: DỰ TOÁN CHI TIẾT THEO CÁC CHỨC DANH THỰC HIỆN ĐỀ TÀI
J2: Đơn vị tính: triệu đồng
A3: STT | B3: Nội dung công việc | C3: Chức danh nghiên cứu | D3: Hệ số lao động khoa học (HCD) | E3: Số người trong nhóm chức danh | F3: Định mức thù lao tháng của chủ nhiệm | G3: Tổng số tháng công quy đổi của nhóm chức danh | H3: Tổng thù lao thực hiện đề tài | I3: Nguồn vốn
B4: Nội dung công việc | I4: Kinh phí Bệnh viện
I5: Năm thứ nhất | J5: Năm thứ hai
A6: 1 | B6: 2 | D6: 3 | E6: 4 | F6: 5 | G6: 6 | H6: 7=3x5x6 | I6: 8 | J6: 9
A7: I | B7: Xây dựng thuyết minh đề tài | C7: Nội dung công việc này chủ nhiệm và thư ký khoa học của nhiệm vụ thực hiện, đã được tính trong thù lao của chủ nhiệm và thư ký khoa học, không tính thù lao riêng.
A8: II | B8: Nội dung nghiên cứu
A9: 1 | B9: Nội dung 1: Xây dựng bộ công cụ đánh giá ngôn ngữ | H9: =H10+H13 -> 6.2836364 | I9: =I10+I13 -> 6.2836364
B10: Công việc 1.1: Tham khảo hệ thống công cụ đánh giá ngôn ngữ quốc tế | H10: =H11+H12 -> 3.1418182 | I10: =H10 -> 3.1418182
B11: Vũ Nguyễn Minh Đức | C11: TVC | D11: 0.48 | E11: 1 | F11: 3 | G11: =32/22 -> 1.4545455 | H11: =D11*F11*G11 -> 2.0945455 | I11: =H11 -> 2.0945455
B12: Lý Minh Đăng | C12: TV | D12: 0.24 | E12: 1 | F12: 3 | G12: =32/22 -> 1.4545455 | H12: =D12*F12*G12 -> 1.0472727 | I12: =H12 -> 1.0472727
B13: Công việc 1.2: Thực hiện dịch xuôi – dịch ngược, điều chỉnh ngữ cảnh tiếng Việt; thử nghiệm sơ bộ (pilot) và hiệu chỉnh. | F13: 3 | H13: =H14+H16+H15 -> 3.1418182 | I13: =H13 -> 3.1418182
B14: Vũ Nguyễn Minh Đức | C14: TVC | D14: 0.48 | E14: 1 | F14: 3 | G14: =24/22 -> 1.0909091 | H14: =D14*F14*G14 -> 1.5709091 | I14: =H14 -> 1.5709091
B15: Lý Minh Đăng | C15: TV | D15: 0.24 | E15: 1 | F15: 3 | G15: =24/22 -> 1.0909091 | H15: =D15*F15*G15 -> 0.78545455 | I15: =H15 -> 0.78545455
B16: Phan Xuân Uy Hùng | C16: TV | D16: 0.24 | E16: 1 | F16: 3 | G16: =24/22 -> 1.0909091 | H16: =D16*F16*G16 -> 0.78545455 | I16: =H16 -> 0.78545455
A17: 2 | B17: Nội dung 2: Đánh giá đặc điểm chức năng ngôn ngữ ở người lớn tuổi bình thường, Suy giảm nhận thức nhẹ và bệnh Alzheimer | F17: 3 | H17: =H18+H23 -> 12.763636 | I17: =I18+I23 -> 12.763636
B18: Công việc 2.1: Thu thập dữ liệu. | F18: 3 | H18: =H22+H19+H20+H21 -> 11.52 | I18: =I22+I19+I20+I21 -> 11.52
B19: Hoàng Tiến Trọng Nghĩa | C19: TVC | D19: 0.48 | E19: 1 | F19: 3 | G19: =32/22 -> 1.4545455 | H19: =D19*F19*G19 -> 2.0945455 | I19: =H19 -> 2.0945455
B20: Lý Minh Đăng | C20: TV | D20: 0.24 | E20: 1 | F20: 3 | G20: =96/22 -> 4.3636364 | H20: =D20*F20*G20 -> 3.1418182 | I20: =H20 -> 3.1418182
B21: Phan Ngọc Minh Thư | C21: TV | D21: 0.24 | E21: 1 | F21: 3 | G21: =96/22 -> 4.3636364 | H21: =D21*F21*G21 -> 3.1418182 | I21: =H21-J19 -> 3.1418182
B22: Phan Xuân Uy Hùng | C22: TV | D22: 0.24 | E22: 1 | F22: 3 | G22: =96/22 -> 4.3636364 | H22: =D22*F22*G22 -> 3.1418182 | I22: =H22 -> 3.1418182
B23: Công việc 2.2: Thống kê mô tả đặc điểm ngôn ngữ từng nhóm. Phân tích sự khác biệt bằng các phép kiểm thống kê (ANOVA, Kruskal-Wallis, t-test...). | F23: 3 | H23: =H26+H25+H24 -> 1.2436364 | I23: =H23 -> 1.2436364
B24: Hoàng Tiến Trọng Nghĩa | C24: TVC | D24: 0.48 | E24: 1 | F24: 3 | G24: =4/22 -> 0.18181818 | H24: =D24*F24*G24 -> 0.26181818 | I24: 0.96
B25: Lý Minh Đăng | C25: TV | D25: 0.24 | E25: 1 | F25: 3 | G25: =15/22 -> 0.68181818 | H25: =D25*F25*G25 -> 0.49090909 | I25: =H25-J25 -> 0.49090909
B26: Phan Ngọc Minh Thư | C26: TV | D26: 0.24 | E26: 1 | F26: 3 | G26: =15/22 -> 0.68181818 | H26: =D26*F26*G26 -> 0.49090909 | I26: =H26-J24 -> 0.49090909
A27: 3 | B27: Nội dung 3: Xây dựng mô hình ứng dụng thông minh dùng để chẩn đoán sớm và từ xa dành cho người cao tuổi có suy giảm ngôn ngữ | F27: 3 | H27: =H28+H32+H36 -> 3.7309091 | I27: =I28+I32+I36 -> 3.7309091
B28: Công việc 3.1: Chuẩn hoá dữ liệu lời nói, trích xuất đặc trưng | F28: 3 | H28: =H29+H31+H30 -> 1.2436364 | I28: =I29+I31+I30 -> 1.2436364
B29: Hà Thị Thanh Hương | C29: TVC | D29: 0.48 | E29: 1 | F29: 3 | G29: =4/22 -> 0.18181818 | H29: =D29*F29*G29 -> 0.26181818 | I29: =H29-J29 -> 0.26181818
B30: Phan Ngọc Minh Thư | C30: TV | D30: 0.24 | E30: 1 | F30: 3 | G30: =15/22 -> 0.68181818 | H30: =D30*F30*G30 -> 0.49090909 | I30: =H30-J28 -> 0.49090909
B31: Phan Xuân Uy Hùng | C31: TV | D31: 0.24 | E31: 1 | F31: 3 | G31: =15/22 -> 0.68181818 | H31: =D31*F31*G31 -> 0.49090909 | I31: =H31-J29 -> 0.49090909
B32: Công việc 3.2: Xây dựng mô hình phân loại | F32: 3 | H32: =H33+H35+H34 -> 1.2436364 | I32: =I33+I35+I34 -> 1.2436364
B33: Hà Thị Thanh Hương | C33: TVC | D33: 0.48 | E33: 1 | F33: 3 | G33: =4/22 -> 0.18181818 | H33: =D33*F33*G33 -> 0.26181818 | I33: =H33-J33 -> 0.26181818
B34: Lý Minh Đăng | C34: TV | D34: 0.24 | E34: 1 | F34: 3 | G34: =15/22 -> 0.68181818 | H34: =D34*F34*G34 -> 0.49090909 | I34: =H34-J34 -> 0.49090909
B35: Phan Ngọc Minh Thư | C35: TV | D35: 0.24 | E35: 1 | F35: 3 | G35: =15/22 -> 0.68181818 | H35: =D35*F35*G35 -> 0.49090909 | I35: =H35-J35 -> 0.49090909
B36: Công việc 3.3: Huấn luyện – kiểm định mô hình. | F36: 3 | H36: =H39+H37+H38 -> 1.2436364 | I36: =H36-J36 -> 1.2436364
B37: Hà Thị Thanh Hương | C37: TVC | D37: 0.48 | E37: 1 | F37: 3 | G37: =4/22 -> 0.18181818 | H37: =D37*F37*G37 -> 0.26181818 | I37: =H37-J37 -> 0.26181818
B38: Phan Xuân Uy Hùng | C38: TV | D38: 0.24 | E38: 1 | F38: 3 | G38: =15/22 -> 0.68181818 | H38: =D38*F38*G38 -> 0.49090909 | I38: =H38-J38 -> 0.49090909
B39: Phan Ngọc Minh Thư | C39: TV | D39: 0.24 | E39: 1 | F39: 3 | G39: =15/22 -> 0.68181818 | H39: =D39*F39*G39 -> 0.49090909 | I39: =H39-J39 -> 0.49090909
A40: 4 | B40: Thù lao của Chủ nhiệm đề tài | C40: CNĐT | D40: 0.6 | E40: 1 | F40: 3 | G40: =0.2*12 -> 2.4 | H40: =D40*F40*G40 -> 4.32 | I40: =H40 -> 4.32
...

Sheet 2. Nguyên vật liệu
A1: Khoản 3. Nguyên vật liệu, năng lượng
A3: TT | B3: Nội dung | C3: Đơn vị đo | D3: Số lượng | E3: Đơn giá (triệu đồng) | F3: Thành tiền (triệu đồng) | G3: Nguồn vốn
G4: Kinh phí Bệnh viện | M4: Tự có | N4: Khác
G5: Tổng số | H5: Trong đó, khoán chi theo quy định* | I5: Năm thứ nhất | J5: Trong đó, khoán chi theo quy định* | K5: Năm thứ hai | L5: Trong đó, khoán chi theo quy định *
A6: 1 | B6: 2 | C6: 3 | D6: 4 | E6: 5 | F6: 6 | G6: 7 | H6: 8 | I6: 9 | J6: 10 | K6: 11 | L6: 12 | M6: 15 | N6: 16
A7: 1 | B7: Nguyên, vật liệu
A8: II | B8: Dụng cụ, phụ tùng, vật rẻ tiền mau hỏng
A9: III | B9: Năng lượng, nhiên liệu
B10: - Than
B11: - Điện | C11: kW/h
B12: - Xăng, dầu
B13: - Nhiên liệu khác
A14: IV | B14: Nước | C14: m3
B16: Cộng:

Sheet Sheet1
A1: TT | D1: 1 | E1: 1 | F1: 2
A2: Nội dung | D2: 2 | E2: Nguyên, vật liệu (Dự toán chi tiết theo thứ tự nội dung nghiên cứu nêu tại mục 17 của thuyết minh) | F2: Nội dung 1: Tổng hợp các tài liệu nghiên cứu về ung thư đại trực tràng, liên quan tới đề tài nghiên cứu; Khảo sát thực tế tính khả thi và tiến hành thu thập đầy đủ thông tin hành chính, lâm sàng, cận lâm sàng | G2: Dao cắt mô | H2: Ống nghiệm chống đông máu EDTA | I2: XN: sinh hóa máu ( ure, glucose, creatinin, acid uric, SGOT, SGPT, Albumin, Protein, CEA) cho 300 mẫu | J2: XN Huyết đồ 300 mẫu | K2: XN nước tiểu (11 thông số) | L2: XQ phổi tim phổi thẳng | M2: Nội dung 2+3: Xây dựng mẫu chuẩn và xác định tỷ lệ methyl hóa ở mẫu mô ung thư/liền kề; mẫu máu ở bệnh nhân ung thư vú | N2: Sử dụng kỹ thuật qPCR để xác định tỷ lệ methyl hóa BRCA1/ RASSF1A | O2: Monarch® Genomic DNA Purification Kit (50 phản ứng/hộp) | P2: 100 bp DNA Ladder (0.1mL/ống) | Q2: 50 bp DNA Ladder (0.1mL/ống) | R2: 1kb DNA Ladder (0.1mL/ống) | S2: Monarch® PCR & DNA Cleanup Kit (50 phản ứng/hộp) | T2: Monarch® Plasmid Miniprep Kit (50 phản ứng/hộp) | U2: NEBuilder® HiFi DNA Assembly Cloning Kit (10 phản ứng/hộp) | V2: Luna® Universal qPCR Master Mix (200 phản ứng/hộp) | W2: GoTaq G2 Hot Start Green Mastermix (2000 phản ứng/25mL) | X2: MagMax Cell Free DNA Isolation Kit | Y2: Human Methylated & Non-methylated DNA Set | Z2: EZ DNA Methylation Gold Kit | AA2: Mồi đặc hiệu methyl hóa cho BRCA1, RASSF1A, ACTB | AB2: Sanger sequencing kit | AC2: Ethanol (96%) | AD2: Xylene | AE2: Proteinase K | AF2: Agarose MP | AG2: Tris Base | AH2: Acid Boric | AI2: Temed | AJ2: Phenol | AK2: Chloroform | AL2: TBE buffer (Tris-Borate-EDTA), 5x Solution | AM2: Acryl/Bis solution(37.5: 1), 40% (w/v) | AN2: Amonium Persulphate (APS) | AO2: Bromophenol Blue | AP2: Hộp giữ DNA, RNA ở lạnh sâu | AQ2: DyeAll Staining Solution | AR2: abWare™ qPCR Strips & Flat 8- cap Strips | AS2: Đầu típ trắng (10 µl) | AT2: Đầu tip vàng (200 µl) | AU2: Đầu tip xanh (1000 µl) | AV2: Ống falcon 50 ml | AW2: Eppendoft 1.7mL (1000 chiếc/hộp) | AX2: Epp PCR thường (1000 chiếc/hộp) | AY2: Chai Duran 1000 ml | AZ2: Chai Duran 500 ml | BA2: Giấy parafilm | BB2: Bản kính điện di | BC2: Lược bản gel acrylamide
A3: Đơn vị đo | D3: 3 | G3: Cái | H3: Hộp | I3: Mẫu | J3: Mẫu | K3: Mẫu | L3: Mẫu | O3: bộ | P3: ml | Q3: ml | R3: ml | S3: bộ | T3: bộ | U3: bộ | V3: bộ | W3: bộ | X3: bộ | Y3: bộ | Z3: bộ | AA3: nucleotid | AB3: bộ | AC3: 500ml | AD3: 500ml | AE3: ml | AF3: 100g | AG3: 1kg | AH3: 500g | AI3: ml | AJ3: 500ml | AK3: 500ml | AL3: lít | AM3: 500ml | AN3: gam | AO3: gam | AP3: hộp | AQ3: ml | AR3: hộp | AS3: túi | AT3: túi | AU3: túi | AV3: túi | AW3: hộp | AX3: hộp | AY3: chai | AZ3: chai | BA3: cuộn | BB3: hộp | BC3: hộp
A4: Số lượng | D4: 4 | G4: 200 | H4: 2 | I4: 200 | J4: 200 | K4: 200 | L4: 200 | O4: 4 | P4: 3 | Q4: 3 | R4: 2 | S4: 2 | T4: 2 | U4: 2 | V4: 5 | W4: 2 | X4: 4 | Y4: 2 | Z4: 4 | AA4: =12*23 -> 276 | AB4: 1 | AC4: 10 | AD4: 10 | AE4: 3 | AF4: 2 | AG4: 2 | AH4: 2 | AI4: 2 | AJ4: 2 | AK4: 2 | AL4: 2 | AM4: 2 | AN4: 2 | AO4: 2 | AP4: 15 | AQ4: 2 | AR4: 30 | AS4: 50 | AT4: 50 | AU4: 30 | AV4: 30 | AW4: 50 | AX4: 10 | AY4: 15 | AZ4: 15 | BA4: 2 | BB4: 5 | BC4: 2
A5: Đơn giá (triệu đồng) | D5: 5 | G5: 0.1 | H5: 0.5 | I5: 0.4 | J5: 0.08 | K5: 0.05 | L5: 0.08 | O5: 6.14 | P5: 2.7 | Q5: 3.2 | R5: 2.8 | S5: 4.2 | T5: 3.42 | U5: 6.79 | V5: 4.64 | W5: 14 | X5: 16 | Y5: 12.8 | Z5: 16 | AA5: 0.5 | AB5: 25 | AC5: 0.65 | AD5: 0.132 | AE5: 3.7 | AF5: 3.6 | AG5: 1.16 | AH5: 0.6 | AI5: 0.43 | AJ5: 6.7 | AK5: 2.6 | AL5: 1.6 | AM5: 2.3 | AN5: 1.1 | AO5: 1.65 | AP5: 0.075 | AQ5: 0.9 | AR5: 2.98 | AS5: 0.3 | AT5: 0.2 | AU5: 0.46 | AV5: 0.235 | AW5: 0.62 | AX5: 1.2 | AY5: 0.35 | AZ5: 0.3 | BA5: 1.1 | BB5: 1.9 | BC5: 1.2
A6: Thành tiền (triệu đồng) | D6: 6 | E6: =SUM(F6:BC6) -> 854.905 | G6: =G4*G5 -> 20 | H6: =H4*H5 -> 1 | I6: =I4*I5 -> 80 | J6: =J4*J5 -> 16 | K6: =K4*K5 -> 10 | L6: =L4*L5 -> 16 | O6: =O4*O5 -> 24.56 | P6: =P4*P5 -> 8.1 | Q6: =Q4*Q5 -> 9.6 | R6: =R4*R5 -> 5.6 | S6: =S4*S5 -> 8.4 | T6: =T4*T5 -> 6.84 | U6: =U4*U5 -> 13.58 | V6: =V4*V5 -> 23.2 | ... AB6: =AB4*AB5 -> 25 | AC6: =AC5*AC4 -> 6.5 | AD6: =AD5*AD4 -> 1.32 | AE6: =AE5*AE4 -> 11.1 | AF6: =AF5*AF4 -> 7.2 | AG6: =AG5*AG4 -> 2.32 | AH6: =AH5*AH4 -> 1.2 | AI6: =AI5*AI4 -> 0.86 | AJ6: =AJ5*AJ4 -> 13.4 | ... AX6: =AX5*AX4 -> 12 | AY6: =AY4*AY5 -> 5.25 | AZ6: =AZ4*AZ5 -> 4.5 | BA6: =BA4*BA5 -> 2.2 | BB6: =BB4*BB5 -> 9.5 | BC6: =BC4*BC5 -> 2.4
A7: Nguồn vốn | B7: Ngân sách SNKH | C7: Tổng số | D7: 7 | E7: =SUM(F7:BC7) -> 854.905 | G7: =G6 -> 20 | H7: =H6 -> 1 | I7: =I6 -> 80 | J7: =J6 -> 16 | K7: =K6 -> 10 | L7: =L6 -> 16 | O7: =O6 -> 24.56 | P7: =P6 -> 8.1 | Q7: =Q6 -> 9.6 | R7: =R6 -> 5.6 | S7: =S6 -> 8.4 | T7: =T6 -> 6.84 | U7: =U6 -> 13.58 | V7: =V6 -> 23.2 | ... BC7: =BC6 -> 2.4
C8: Trong đó, khoán chi theo quy định* | D8: 8 | E8: =SUM(F8:BC8) -> 0
C9: Năm 2027 | D9: 9 | E9: =SUM(F9:BC9) -> 854.905 | G9: =G7 -> 20 | H9: =H7 -> 1 | I9: =I7 -> 80 | J9: =J7 -> 16 | K9: =K7 -> 10 | L9: =L7 -> 16 | O9: =O7 -> 24.56 | P9: =P7 -> 8.1 | Q9: =Q7 -> 9.6 | R9: =R7 -> 5.6 | S9: =S7 -> 8.4 | T9: =T7 -> 6.84 | U9: =U7 -> 13.58 | V9: =V7 -> 23.2 | ... BC9: =BC7 -> 2.4
C10: Trong đó, khoán chi theo quy định* | D10: 10 | E10: =SUM(F10:BC10) -> 0
C11: Năm 2028 | D11: 11 | E11: =SUM(F11:BC11) -> 0
C12: Trong đó, khoán chi theo quy định * | D12: 12 | E12: =SUM(F12:BC12) -> 0
B13: Tự có | D13: 15
B14: Khác | D14: 16

Sheet 3. Thiết bị,máy móc
A1: Khoản 4. THIẾT BỊ, MÁY MÓC
A3: TT | B3: Nội dung | C3: Số lượng | D3: Đơn giá | E3: Thành tiền | F3: Nguồn vốn
F4: Kinh phí Bệnh viện | I4: Tự có | J4: Khác
F5: Tổng | G5: Năm thứ nhất* | H5: Năm thứ hai*
A7: 1 | B7: 2 | C7: 3 | D7: 4 | E7: 5 | F7: 6 | G7: 7 | H7: 8 | I7: 10 | J7: 11
A8: I | B8: Thiết bị hiện có của đơn vị chủ trì thực hiện đề tài
A9: 1
A10: 2
A11: II | B11: Thiết bị, máy móc điều chuyển từ đơn vị khác đến
A12: III | B12: Khấu hao thiết bị
A13: IV | B13: Thuê thiết bị (ghi tên thiết bị, thời gian thuê)
A14: V | B14: Thiết bị, công nghệ mua mới
A15: VI | B15: Vận chuyển lắp đặt
A16: VII | B16: Bảo dưỡng, sửa chữa
B18: Cộng:

Sheet 4. Xây dựng, sửa chữa nhỏ
A1: Khoản 5. XÂY DỰNG, SỬA CHỮA NHỎ
A3: TT | B3: Nội dung | C3: Kinh phí | D3: Nguồn vốn
D4: Kinh phí Bệnh viện | G4: Tự có | H4: Khác
D5: Tổng | E5: Năm thứ nhất* | F5: Năm thứ hai*
A6: 1 | B6: 2 | C6: 3 | D6: 4 | E6: 5 | F6: 6 | G6: 8 | H6: 9
A7: 1 | B7: Chi phí xây dựng ...... m2 nhà xưởng, PTN
A9: 2 | B9: Chi phí sửa chữa ....... m2 nhà xưởng, PTN
A11: 3 | B11: Chi phí lắp đặt hệ thống điện, nước
A13: 4 | B13: Chi phí khác
B15: Cộng:

Sheet 5. Chi khác
B1: Khoản 6. CHI KHÁC
A3: TT | B3: Nội dung | C3: Tổng số | E3: Nguồn vốn
C4: Kinh phí | D4: Tỷ lệ (%) | E4: Kinh phí Bệnh viện | K4: Tự có | L4: Khác
E5: Tổng số | F5: Trong đó, khoán chi theo quy định* | G5: Năm thứ nhất | H5: Trong đó, khoán chi theo quy định* | I5: Năm thứ hai | J5: Trong đó, khoán chi theo quy định *
A6: 1 | B6: 2 | C6: 3 | D6: 4 | E6: 5 | F6: 6 | G6: 7 | H6: 8 | I6: 9 | J6: 10 | K6: 13 | L6: 14
A7: 1 | B7: Chi điều tra, khảo sát thu thập số liệu, công tác trong nước
A8: 2 | B8: Hợp tác quốc tế (định mức chi theo quy định hiện hành)
A9: 3 | B9: Kinh phí quản lý (bằng 5% tổng kinh phí thực hiện đề tài, tối đa không quá 300 triệu đồng) | C9: =('Tổng kinh phí'!C8)/95*5 -> 1.4944306 | E9: =C9 -> 1.4944306 | F9: =E9 -> 1.4944306 | G9: =E9 -> 1.4944306 | H9: =F9 -> 1.4944306
A10: 4 | B10: Chi phí đánh giá, kiểm tra nội bộ
A11: 5 | B11: Chi trả dịch vụ thuê ngoài phục vụ hoạt động nghiên cứu
A12: 6 | B12: Chi khác
A13: 6.1 | B13: Hội thảo (trong nước) (Theo thông tư 40/2017/TT-BTC)
A14: 6.2 | B14: Ấn loát tài liệu, văn phòng phẩm
B15: Cộng: | C15: =C7+C8+C9+C10+C11+C12 -> 1.4944306 | E15: =E7+E8+E9+E10+E11+E12 -> 1.4944306 | F15: =F7+F8+F9+F10+F11+F12 -> 1.4944306 | G15: =G7+G8+G9+G10+G11+G12 -> 1.4944306 | H15: =H7+H8+H9+H10+H11+H12 -> 1.4944306
